<?xml version="1.0" encoding="utf-8"?><testsuites><testsuite name="pytest" errors="1" failures="0" skipped="0" tests="2" time="11.001" timestamp="2021-07-16T11:24:17.410869" hostname="DESKTOP-85SU4SE"><testcase classname="test_dir.test_baidu.TestSearch" name="test_baidu_search_case" time="5.555" /><testcase time="0.000" /><testcase classname="pytest" name="internal" time="0.000"><error message="internal error">Traceback (most recent call last):
  File "C:\Users\llo\AppData\Local\Programs\Python\Python39\lib\site-packages\_pytest\main.py", line 269, in wrap_session
    session.exitstatus = doit(config, session) or 0
  File "C:\Users\llo\AppData\Local\Programs\Python\Python39\lib\site-packages\_pytest\main.py", line 323, in _main
    config.hook.pytest_runtestloop(session=session)
  File "C:\Users\llo\AppData\Local\Programs\Python\Python39\lib\site-packages\pluggy\hooks.py", line 286, in __call__
    return self._hookexec(self, self.get_hookimpls(), kwargs)
  File "C:\Users\llo\AppData\Local\Programs\Python\Python39\lib\site-packages\pluggy\manager.py", line 93, in _hookexec
    return self._inner_hookexec(hook, methods, kwargs)
  File "C:\Users\llo\AppData\Local\Programs\Python\Python39\lib\site-packages\pluggy\manager.py", line 84, in &lt;lambda&gt;
    self._inner_hookexec = lambda hook, methods, kwargs: hook.multicall(
  File "C:\Users\llo\AppData\Local\Programs\Python\Python39\lib\site-packages\pluggy\callers.py", line 208, in _multicall
    return outcome.get_result()
  File "C:\Users\llo\AppData\Local\Programs\Python\Python39\lib\site-packages\pluggy\callers.py", line 80, in get_result
    raise ex[1].with_traceback(ex[2])
  File "C:\Users\llo\AppData\Local\Programs\Python\Python39\lib\site-packages\pluggy\callers.py", line 187, in _multicall
    res = hook_impl.function(*args)
  File "C:\Users\llo\AppData\Local\Programs\Python\Python39\lib\site-packages\_pytest\main.py", line 348, in pytest_runtestloop
    item.config.hook.pytest_runtest_protocol(item=item, nextitem=nextitem)
  File "C:\Users\llo\AppData\Local\Programs\Python\Python39\lib\site-packages\pluggy\hooks.py", line 286, in __call__
    return self._hookexec(self, self.get_hookimpls(), kwargs)
  File "C:\Users\llo\AppData\Local\Programs\Python\Python39\lib\site-packages\pluggy\manager.py", line 93, in _hookexec
    return self._inner_hookexec(hook, methods, kwargs)
  File "C:\Users\llo\AppData\Local\Programs\Python\Python39\lib\site-packages\pluggy\manager.py", line 84, in &lt;lambda&gt;
    self._inner_hookexec = lambda hook, methods, kwargs: hook.multicall(
  File "C:\Users\llo\AppData\Local\Programs\Python\Python39\lib\site-packages\pluggy\callers.py", line 208, in _multicall
    return outcome.get_result()
  File "C:\Users\llo\AppData\Local\Programs\Python\Python39\lib\site-packages\pluggy\callers.py", line 80, in get_result
    raise ex[1].with_traceback(ex[2])
  File "C:\Users\llo\AppData\Local\Programs\Python\Python39\lib\site-packages\pluggy\callers.py", line 187, in _multicall
    res = hook_impl.function(*args)
  File "C:\Users\llo\AppData\Local\Programs\Python\Python39\lib\site-packages\_pytest\runner.py", line 109, in pytest_runtest_protocol
    runtestprotocol(item, nextitem=nextitem)
  File "C:\Users\llo\AppData\Local\Programs\Python\Python39\lib\site-packages\_pytest\runner.py", line 126, in runtestprotocol
    reports.append(call_and_report(item, "call", log))
  File "C:\Users\llo\AppData\Local\Programs\Python\Python39\lib\site-packages\_pytest\runner.py", line 217, in call_and_report
    report: TestReport = hook.pytest_runtest_makereport(item=item, call=call)
  File "C:\Users\llo\AppData\Local\Programs\Python\Python39\lib\site-packages\pluggy\hooks.py", line 286, in __call__
    return self._hookexec(self, self.get_hookimpls(), kwargs)
  File "C:\Users\llo\AppData\Local\Programs\Python\Python39\lib\site-packages\pluggy\manager.py", line 93, in _hookexec
    return self._inner_hookexec(hook, methods, kwargs)
  File "C:\Users\llo\AppData\Local\Programs\Python\Python39\lib\site-packages\pluggy\manager.py", line 84, in &lt;lambda&gt;
    self._inner_hookexec = lambda hook, methods, kwargs: hook.multicall(
  File "C:\Users\llo\AppData\Local\Programs\Python\Python39\lib\site-packages\pluggy\callers.py", line 203, in _multicall
    gen.send(outcome)
  File "C:\Users\llo\.jenkins\workspace\Simple task1\conftest.py", line 52, in pytest_runtest_makereport
    capture_screenshots(case_name)
  File "C:\Users\llo\.jenkins\workspace\Simple task1\conftest.py", line 99, in capture_screenshots
    RunConfig.driver.save_screenshot(image_dir)
  File "C:\Users\llo\AppData\Local\Programs\Python\Python39\lib\site-packages\selenium\webdriver\remote\webdriver.py", line 1055, in save_screenshot
    return self.get_screenshot_as_file(filename)
  File "C:\Users\llo\AppData\Local\Programs\Python\Python39\lib\site-packages\selenium\webdriver\remote\webdriver.py", line 1032, in get_screenshot_as_file
    png = self.get_screenshot_as_png()
  File "C:\Users\llo\AppData\Local\Programs\Python\Python39\lib\site-packages\selenium\webdriver\remote\webdriver.py", line 1064, in get_screenshot_as_png
    return base64.b64decode(self.get_screenshot_as_base64().encode('ascii'))
  File "C:\Users\llo\AppData\Local\Programs\Python\Python39\lib\site-packages\selenium\webdriver\remote\webdriver.py", line 1074, in get_screenshot_as_base64
    return self.execute(Command.SCREENSHOT)['value']
  File "C:\Users\llo\AppData\Local\Programs\Python\Python39\lib\site-packages\selenium\webdriver\remote\webdriver.py", line 321, in execute
    self.error_handler.check_response(response)
  File "C:\Users\llo\AppData\Local\Programs\Python\Python39\lib\site-packages\selenium\webdriver\remote\errorhandler.py", line 241, in check_response
    raise exception_class(message, screen, stacktrace, alert_text)
selenium.common.exceptions.UnexpectedAlertPresentException: Alert Text: 已经记录下您的使用偏好
Message: unexpected alert open: {Alert text : 已经记录下您的使用偏好}
  (Session info: chrome=91.0.4472.124)</error></testcase></testsuite></testsuites>